Workbook

Sheet juillet 2023
C1: Chris | D1: Alex
A2: Alimentation | B2: marché/pain | D2: =5+12+14+6+15 -> 52
B3: miel
B4: Viande | C4: 57
B5: Intermarché | C5: =2 -> 2 | D5: =95+9+82+75+124+58 -> 443
A6: Habitation | B6: Loyer
B7: vanille | C7: 51
A8: Total | C8: =SUM(C2:C7) -> 110 | D8: =SUM(D2:D7) -> 495
B9: Assurance | D9: 24
B10: Impôt
B11: Eau
B12: direct énergie | D12: 190
B13: Internet | C13: 30
B14: Taxe habitation
B15: Ramonage
B16: netflix
A17: Total | C17: =SUM(C9:C16) -> 30 | D17: =SUM(D9:D16) -> 214
A18: Loisirs | B18: Restaurant | D18: 37
B19: Week-end/vacances | C19: 106 | D19: 18
B20: Livres
A21: Total | C21: =sum(C18:C20) -> 106 | D21: =sum(D18:D20) -> 55
A22: Vie quotidienne | B22: pharmacie
B23: Berlioz/rats | C23: 99
B24: Sport
B25: Cadeaux
B26: Appartement | C26: =5+27+13 -> 45 | D26: 25
B27: Immo
A28: Total | C28: =sum(C22:C27) -> 144 | D28: =sum(D22:D27) -> 25
A29: Total
A30: Total Chris | D30: =C8+C17+C21+C28 -> 390
A31: Total Alex | D31: =D8+D17+D21+D28 -> 789
A32: Balance | D32: =(D31-D30)/2 -> 199.5
A34: Dettes:
A35: Chris → Alex | B35: Montant | F35: Alex → Chris | G35: Montant | I35: Balance finale (Chris->Alex) | J35: =B42-G42 -> -662.5
A36: Balance courante | B36: =D32 -> 199.5 | F36: Virement | G36: 600
A37: Balence précédente | B37: -385 | I37: Synthèse
A38: appart | B38: 115 | G38: 0 | I38: Total habitation / personne | J38: =D17/2 -> 107
B39: 8 | I39: Total alimentation / personne | J39: =D8/2 -> 247.5
I40: Total loisir / personne | J40: =D21/2 -> 27.5
I41: Total vie quotidienne / personne | J41: =D28/2 -> 12.5
...

Sheet août 2023
C1: Chris | D1: Alex
A2: Alimentation | B2: marché/pain | D2: =9+10+21+4+21 -> 65
B3: miel
B4: Viande
B5: Intermarché | D5: =103+120+186 -> 409
A6: Habitation | B6: Loyer
B7: vanille
C8: =SUM(C2:C7) -> 0 | D8: =SUM(D2:D7) -> 474
B9: Assurance | D9: 26
B10: Impôt
B11: Eau
B12: direct énergie | D12: 216
B13: Internet | C13: 30
B14: Taxe habitation
B15: Ramonage | C15: =1007 -> 1007
B16: netflix
A17: Total | C17: =SUM(C9:C16) -> 1037 | D17: =SUM(D9:D16) -> 242
A18: Loisirs | B18: Restaurant | C18: =44 -> 44
B19: Week-end/vacances | C19: =90+12+50+29+9+43+51 -> 284 | D19: =160+4+206+40+38+3 -> 451
B20: Livres
A21: Total | C21: =sum(C18:C20) -> 328 | D21: =sum(D18:D20) -> 451
A22: Vie quotidienne | B22: pharmacie
B23: Berlioz/rats | D23: 56
B24: Sport
B25: Cadeaux | D25: 16
B26: Appartement
B27: Immo
A28: Total | C28: =sum(C22:C27) -> 0 | D28: =sum(D22:D27) -> 72
A29: Total
A30: Total Chris | D30: =C8+C17+C21+C28 -> 1365
A31: Total Alex | D31: =D8+D17+D21+D28 -> 1239
A32: Balance | D32: =(D31-D30)/2 -> -63
A34: Dettes:
A35: Chris → Alex | B35: Montant | F35: Alex → Chris | G35: Montant | I35: Balance finale (Chris->Alex) | J35: =B42-G42 -> -858
A36: Balance courante | B36: =D32 -> -63 | F36: Virement | G36: 200
A37: Balence précédente | B37: -663 | F37: amaretto | G37: 54 | I37: Synthèse
A38: appart | B38: 115 | G38: 0 | I38: Total habitation / personne | J38: =D17/2 -> 121
A39: pile montre | B39: 7 | I39: Total alimentation / personne | J39: =D8/2 -> 237
I40: Total loisir / personne | J40: =D21/2 -> 225.5
I41: Total vie quotidienne / personne | J41: =D28/2 -> 36
...

Sheet septembre 2023
C1: Chris | D1: Alex
A2: Alimentation | B2: marché/pain | D2: =19+5+18+25+3+2+20+3+6 -> 101
B3: miel
B4: Viande | D4: =30+53 -> 83
B5: Intermarché | C5: =8+4+12 -> 24 | D5: =98+8+117+76+104+127 -> 530
A6: Habitation | B6: Loyer
B7: vanille
C8: =SUM(C2:C7) -> 24 | D8: =SUM(D2:D7) -> 714
B9: Assurance | D9: 26
B10: Impôt
B11: Eau
B12: direct énergie | D12: 216
B13: Internet
B14: Taxe habitation
B15: Ramonage
B16: netflix
A17: Loisirs | B17: Restaurant
A18: Total | C18: =SUM(C9:C16) -> 0 | D18: =SUM(D9:D16) -> 242
B19: Week-end/vacances | D19: 100
B20: Livres
A21: Total | C21: =SUM(C17:C19) -> 0 | D21: =SUM(D19:D20) -> 100
A22: Vie quotidienne | B22: pharmacie
B23: Berlioz/rats
B24: Sport
B25: Cadeaux
B26: Appartement | D26: =8+70+8+440 -> 526
B27: Immo
A28: Total | C28: =sum(C22:C27) -> 0 | D28: =sum(D22:D27) -> 526
A29: Total
A30: Total Chris | D30: =C8+C18+C21+C28 -> 24
A31: Total Alex | D31: =D8+D18+D21+D28 -> 1582
A32: Balance | D32: =(D31-D30)/2 -> 779
A34: Dettes:
A35: Chris → Alex | B35: Montant | F35: Alex → Chris | G35: Montant | I35: Balance finale (Chris->Alex) | J35: =B42-G42 -> 142
A36: Balance courante | B36: =D32 -> 779 | F36: Virement
A37: Balence précédente | B37: -858 | I37: Synthèse
A38: appart | B38: 115 | G38: 0 | I38: Total habitation / personne | J38: =D18/2 -> 121
A39: miel | B39: 17 | I39: Total alimentation / personne | J39: =D8/2 -> 357
A40: pharma | B40: 19 | I40: Total loisir / personne | J40: =D21/2 -> 50
A41: cathy | B41: 70 | I41: Total vie quotidienne / personne | J41: =D28/2 -> 263
...

Sheet octobre 2023
C1: Chris | D1: Alex
A2: Alimentation | B2: marché/pain | D2: =10+8+11+11 -> 40
B3: miel
B4: Viande | D4: =31+13+21+39 -> 104
B5: Intermarché | D5: =122+134+132+68 -> 456
A6: Habitation | B6: Loyer
B7: vanille
C8: =SUM(C2:C7) -> 0 | D8: =SUM(D2:D7) -> 600
B9: Assurance | D9: 26
B10: Impôt
B11: Eau
B12: direct énergie | D12: 216
B13: Internet | C13: 9
B14: Taxe habitation | C14: 1846
B15: Ramonage
B16: netflix
A17: Loisirs | B17: Restaurant
A18: Total | C18: =SUM(C9:C16) -> 1855 | D18: =SUM(D9:D16) -> 242
B19: Week-end/vacances | C19: 18
B20: Livres | D20: 9
A21: Total | C21: =SUM(C19:C20) -> 18 | D21: =SUM(D19:D20) -> 9
A22: Vie quotidienne | B22: pharmacie | C22: 10
B23: Berlioz/rats | D23: 100
B24: Sport
B25: Cadeaux
B26: Appartement
B27: Immo
A28: Total | C28: =sum(C22:C27) -> 10 | D28: =sum(D22:D27) -> 100
A29: Total
A30: Total Chris | D30: =C8+C18+C21+C28 -> 1883
A31: Total Alex | D31: =D8+D18+D21+D28 -> 951
A32: Balance | D32: =(D31-D30)/2 -> -466
A34: Dettes:
A35: Chris → Alex | B35: Montant | F35: Alex → Chris | G35: Montant | I35: Balance finale (Chris->Alex) | J35: =B42-G42 -> -194
A36: Balance courante | B36: =D32 -> -466 | F36: Virement
A37: Balence précédente | B37: 142 | I37: Synthèse
A38: appart | B38: 115 | G38: 0 | I38: Total habitation / personne | J38: =D18/2 -> 121
A39: pneus | B39: 15 | I39: Total alimentation / personne | J39: =D8/2 -> 300
A40: pharma | I40: Total loisir / personne | J40: =D21/2 -> 4.5
A41: cathy | I41: Total vie quotidienne / personne | J41: =D28/2 -> 50
...

Sheet novembre 2023
C1: Chris | D1: Alex
A2: Alimentation | B2: marché/pain | D2: =9+19+5+4+9+4+34+12+4 -> 100
B3: miel
B4: Viande | D4: =23+23+36 -> 82
B5: Intermarché | C5: =2 -> 2 | D5: =84+12+132+97+17+79 -> 421
A6: Habitation | B6: Loyer
B7: vanille
C8: =SUM(C2:C7) -> 2 | D8: =SUM(D2:D7) -> 603
B9: Assurance | D9: 26
B10: Impôt
B11: Eau
B12: direct énergie | D12: 216
B13: Internet | C13: 17
B14: Taxe habitation
B15: Ramonage
B16: netflix
A17: Loisirs | B17: Restaurant
A18: Total | C18: =SUM(C9:C16) -> 17 | D18: =SUM(D9:D16) -> 242
B19: Week-end/vacances
B20: Livres | C20: =8 -> 8
A21: Total | C21: =SUM(C19:C20) -> 8 | D21: =SUM(D19:D20) -> 0
A22: Vie quotidienne | B22: pharmacie
B23: Berlioz/rats
B24: Sport
B25: Cadeaux | D25: =35+20 -> 55
B26: Appartement | C26: 102 | D26: 60
B27: Immo
A28: Total | C28: =sum(C22:C27) -> 102 | D28: =sum(D22:D27) -> 115
A29: Total
A30: Total Chris | D30: =C8+C18+C21+C28 -> 129
A31: Total Alex | D31: =D8+D18+D21+D28 -> 960
A32: Balance | D32: =(D31-D30)/2 -> 415.5
A34: Dettes:
A35: Chris → Alex | B35: Montant | F35: Alex → Chris | G35: Montant | I35: Balance finale (Chris->Alex) | J35: =B42-G42 -> -263.5
A36: Balance courante | B36: =D32 -> 415.5 | F36: Virement | G36: 600
A37: Balence précédente | B37: -194 | F37: pharma | G37: 16 | I37: Synthèse
A38: appart | B38: 115 | G38: 0 | I38: Total habitation / personne | J38: =D18/2 -> 121
A39: apero | B39: 6 | I39: Total alimentation / personne | J39: =D8/2 -> 301.5
A40: noel | B40: 10 | I40: Total loisir / personne | J40: =D21/2 -> 0
A41: cathy | I41: Total vie quotidienne / personne | J41: =D28/2 -> 57.5
...

Sheet décembre 2023
C1: Chris | D1: Alex
A2: Alimentation | B2: marché/pain | D2: =6+4+10+10+24+5 -> 59
B3: miel
B4: Viande | D4: 47
B5: Intermarché | C5: =5 -> 5 | D5: =105+127+94+110+105 -> 541
A6: Habitation | B6: Loyer
B7: vanille
C8: =SUM(C2:C7) -> 5 | D8: =SUM(D2:D7) -> 647
B9: Assurance | D9: 26
B10: Impôt
B11: Eau
B12: direct énergie | D12: 216
B13: Internet | C13: 17
B14: Taxe habitation
B15: Ramonage
B16: netflix
A17: Loisirs | B17: Restaurant
A18: Total | C18: =SUM(C9:C16) -> 17 | D18: =SUM(D9:D16) -> 242
B19: Week-end/vacances | C19: =14 -> 14
B20: Livres | C20: =10 -> 10
A21: Total | C21: =SUM(C19:C20) -> 24 | D21: =SUM(D19:D20) -> 0
A22: Vie quotidienne | B22: pharmacie | C22: =9 -> 9
B23: Berlioz/rats | C23: =6+100 -> 106
B24: Sport
B25: Cadeaux | D25: =30+20+18+26 -> 94
B26: Appartement
B27: Immo
A28: Total | C28: =sum(C22:C27) -> 115 | D28: =sum(D22:D27) -> 94
A29: Total
A30: Total Chris | D30: =C8+C18+C21+C28 -> 161
A31: Total Alex | D31: =D8+D18+D21+D28 -> 983
A32: Balance | D32: =(D31-D30)/2 -> 411
A34: Dettes:
A35: Chris → Alex | B35: Montant | F35: Alex → Chris | G35: Montant | I35: Balance finale (Chris->Alex) | J35: =B42-G42 -> -338
A36: Balance courante | B36: =D32 -> 411 | F36: Virement | G36: 600
A37: Balence précédente | B37: -264 | I37: Synthèse
A38: appart | B38: 115 | G38: 0 | I38: Total habitation / personne | J38: =D18/2 -> 121
A39: apero | I39: Total alimentation / personne | J39: =D8/2 -> 323.5
A40: noel | I40: Total loisir / personne | J40: =D21/2 -> 0
A41: cathy | I41: Total vie quotidienne / personne | J41: =D28/2 -> 47
...

Sheet janvier 2024
C1: Chris | D1: Alex
A2: Alimentation | B2: marché/pain | C2: =18 -> 18 | D2: =13+10+9+3+5+5 -> 45
B3: miel
B4: Viande | D4: 90
B5: Intermarché | C5: =78 -> 78 | D5: =159+122+78+98 -> 457
A6: Habitation | B6: Loyer
B7: vanille
C8: =SUM(C2:C7) -> 96 | D8: =SUM(D2:D7) -> 592
B9: Assurance | D9: =26+398 -> 424
B10: Impôt
B11: Eau
B12: direct énergie | D12: 216
B13: Internet | C13: 5
B14: Taxe habitation
B15: Ramonage
A17: Loisirs | B17: Restaurant | J17: 1468
A18: Total | C18: =SUM(C9:C16) -> 5 | D18: =SUM(D9:D16) -> 640 | J18: 768
B19: Week-end/vacances | C19: =30+768+6 -> 804 | D19: =21+20+1468+14+130 -> 1653 | J19: =J18+J17 -> 2236
B20: Livres | J20: =J19/2 -> 1118
A21: Total | C21: =SUM(C19:C20) -> 804 | D21: =SUM(D19:D20) -> 1653 | J21: =J20-J18 -> 350
A22: Vie quotidienne | B22: pharmacie
B23: Berlioz/rats
B24: Sport
B25: Cadeaux
B26: Appartement | C26: 44 | D26: 15
B27: Immo
A28: Total | C28: =sum(C22:C27) -> 44 | D28: =sum(D22:D27) -> 15
A29: Total
A30: Total Chris | D30: =C8+C18+C21+C28 -> 949
A31: Total Alex | D31: =D8+D18+D21+D28 -> 2900
A32: Balance | D32: =(D31-D30)/2 -> 975.5
A34: Dettes:
A35: Chris → Alex | B35: Montant | F35: Alex → Chris | G35: Montant | I35: Balance finale (Chris->Alex) | J35: =B42-G42 -> -786.5
A36: Balance courante | B36: =D32 -> 975.5 | F36: Virement | G36: =400+1200 -> 1600
A37: Balence précédente | B37: -338 | G37: 25 | I37: Synthèse
A38: appart | B38: 115 | G38: 0 | I38: Total habitation / personne | J38: =D18/2 -> 320
A39: ski rando | B39: 48 | I39: Total alimentation / personne | J39: =D8/2 -> 296
A40: basket | B40: 38 | I40: Total loisir / personne | J40: =D21/2 -> 826.5
A41: cathy | I41: Total vie quotidienne / personne | J41: =D28/2 -> 7.5
A42: Total | B42: =sum(B36:B41) -> 838.5 | F42: Total | G42: =sum(G36:G41) -> 1625 | I42: Total commun / personne | J42: =sum(J38:J41) -> 1450

Sheet février 2024
C1: Chris | D1: Alex
A2: Alimentation | B2: marché/pain | D2: =1+6+5+9+5+5+8+1 -> 40
B3: miel
B4: Viande | D4: 58
B5: Intermarché | D5: =104+125+93+112 -> 434
A6: Habitation | B6: Loyer
B7: vanille
C8: =SUM(C2:C7) -> 0 | D8: =SUM(D2:D7) -> 532
B9: Assurance | D9: 26
B10: Impôt
B11: Eau
B12: direct énergie | D12: 216
B13: Internet | C13: 27 | J13: Reste Battista | K13: 1120.86
B14: Taxe habitation | J14: Apport Chris | K14: 624.36
B15: Ramonage | J15: TTC Battista | K15: =K14+K13 -> 1745.22
K16: =K15/2 -> 872.61 | L16: =K16-K14 -> 248.25
A17: Total | C17: =SUM(C9:C16) -> 27 | D17: =SUM(D9:D16) -> 242 | J17: 768 | K17: Alex | L17: Chris
A18: Loisirs | B18: Restaurant | C18: =107 -> 107 | J18: 1468
B19: Week-end/vacances | D19: 30 | J19: =J17+J18 -> 2236
B20: Livres | J20: =J19/2 -> 1118
A21: Total | C21: =SUM(C18:C20) -> 107 | D21: =SUM(D18:D20) -> 30 | J21: =J20-J17 -> 350
A22: Vie quotidienne | B22: pharmacie | D22: 7
B23: Berlioz/rats | D23: 32
B24: Sport
B25: Cadeaux
B26: Appartement | C26: =180+38 -> 218
B27: Immo
A28: Total | C28: =sum(C22:C27) -> 218 | D28: =sum(D22:D27) -> 39
A29: Total
A30: Total Chris | D30: =C8+C17+C21+C28 -> 352
A31: Total Alex | D31: =D8+D17+D21+D28 -> 843
A32: Balance | D32: =(D31-D30)/2 -> 245.5
A34: Dettes:
A35: Chris → Alex | B35: Montant | F35: Alex → Chris | G35: Montant | I35: Balance finale (Chris->Alex) | J35: =B42-G42 -> -430.5
A36: Balance courante | B36: =D32 -> 245.5 | F36: Virement
A37: Balence précédente | B37: -787 | F37: Reallon | G37: 19 | I37: Synthèse
A38: appart | B38: 115 | G38: 0 | I38: Total habitation / personne | J38: =D17/2 -> 121
A39: pharmacie | B39: 15 | I39: Total alimentation / personne | J39: =D8/2 -> 266
A40: basket | I40: Total loisir / personne | J40: =D21/2 -> 15
A41: cathy | I41: Total vie quotidienne / personne | J41: =D28/2 -> 19.5
...

Sheet mars 2024
C1: Chris | D1: Alex
A2: Alimentation | B2: marché/pain | D2: =8+15+2+13+5+2 -> 45
B3: miel
B4: Viande | D4: =17+54+22+44 -> 137
B5: Intermarché | D5: =61+71+105+95+2+91 -> 425
A6: Habitation | B6: Loyer
B7: vanille
C8: =SUM(C2:C7) -> 0 | D8: =SUM(D2:D7) -> 607
B9: Assurance | D9: 26
B10: Impôt
B11: Eau
B12: direct énergie | D12: 216
B13: Internet | C13: =32 -> 32
B14: Taxe habitation
B15: Ramonage
A17: Total | C17: =SUM(C9:C16) -> 32 | D17: =SUM(D9:D16) -> 242
A18: Loisirs | B18: Restaurant | C18: 49
B19: Week-end/vacances | C19: 20 | D19: =44+69+10+16 -> 139
B20: Livres
A21: Total | C21: =SUM(C18:C20) -> 69 | D21: =SUM(D18:D20) -> 139
A22: Vie quotidienne | B22: pharmacie
B23: Berlioz/rats | D23: 81
B24: Sport
B25: Cadeaux | D25: 50
B26: Appartement | D26: =17+18 -> 35
B27: Immo
A28: Total | C28: =sum(C22:C27) -> 0 | D28: =sum(D22:D27) -> 166
A29: Total
A30: Total Chris | D30: =C8+C17+C21+C28 -> 101
A31: Total Alex | D31: =D8+D17+D21+D28 -> 1154
A32: Balance | D32: =(D31-D30)/2 -> 526.5
A34: Dettes:
A35: Chris → Alex | B35: Montant | F35: Alex → Chris | G35: Montant | I35: Balance finale (Chris->Alex) | J35: =B42-G42 -> -210.5
A36: Balance courante | B36: =D32 -> 526.5 | F36: Virement | G36: 500
A37: Balence précédente | B37: -352 | F37: Reallon | I37: Synthèse
A38: appart | B38: 115 | G38: 0 | I38: Total habitation / personne | J38: =D17/2 -> 121
A39: pharmacie | I39: Total alimentation / personne | J39: =D8/2 -> 303.5
A40: basket | I40: Total loisir / personne | J40: =D21/2 -> 69.5
A41: cathy | I41: Total vie quotidienne / personne | J41: =D28/2 -> 83
A42: Total | B42: =sum(B36:B41) -> 289.5 | F42: Total | G42: =sum(G36:G41) -> 500 | I42: Total commun / personne | J42: =sum(J38:J41) -> 577

Sheet avril 2024
C1: Chris | D1: Alex
A2: Alimentation | B2: marché/pain | C2: 7 | D2: =12+3+4+24+22 -> 65
B3: miel
B4: Viande | D4: =51+41 -> 92
B5: Intermarché | D5: =136+103+106 -> 345
A6: Habitation | B6: Loyer
B7: vanille
C8: =SUM(C2:C7) -> 7 | D8: =SUM(D2:D7) -> 502
B9: Assurance | D9: 26
B10: Impôt
B11: Eau | D11: 207
B12: direct énergie
B13: Internet | C13: =32 -> 32
B14: Taxe habitation
B15: Ramonage
A17: Total | C17: =SUM(C9:C16) -> 32 | D17: =SUM(D9:D16) -> 233
A18: Loisirs | B18: Restaurant
B19: Week-end/vacances | C19: =6+241 -> 247 | D19: =907+86+595 -> 1588
B21: Livres
A22: Total | C22: =SUM(C18:C21) -> 247 | D22: =SUM(D18:D21) -> 1588
A23: Vie quotidienne | B23: pharmacie
B24: Berlioz/rats | D24: 26
B25: Sport
B26: Cadeaux
B27: Appartement
B28: Immo
A29: Total | C29: =sum(C23:C28) -> 0 | D29: =sum(D23:D28) -> 26
A30: Total
A31: Total Chris | D31: =C8+C17+C22+C29 -> 286
A32: Total Alex | D32: =D8+D17+D22+D29 -> 2349
A33: Balance | D33: =(D32-D31)/2 -> 1031.5
A35: Dettes:
A36: Chris → Alex | B36: Montant | F36: Alex → Chris | G36: Montant | I36: Balance finale (Chris->Alex) | J36: =B43-G43 -> -720.5
A37: Balance courante | B37: =D33 -> 1031.5 | F37: Virement | G37: 600
A38: Balence précédente | B38: -234 | F38: malaga | G38: 734 | I38: Synthèse
A39: appart | B39: 115 | F39: total énergie | G39: 299 | I39: Total habitation / personne | J39: =D17/2 -> 116.5
A40: pharmacie | I40: Total alimentation / personne | J40: =D8/2 -> 251
A41: basket | I41: Total loisir / personne | J41: =D22/2 -> 794
A42: cathy | I42: Total vie quotidienne / personne | J42: =D29/2 -> 13
A43: Total | B43: =sum(B37:B42) -> 912.5 | F43: Total | G43: =sum(G37:G42) -> 1633 | I43: Total commun / personne | J43: =sum(J39:J42) -> 1174.5

Sheet mai 2024
C1: Chris | D1: Alex
A2: Alimentation | B2: marché/pain | C2: 2 | D2: =24+26+17+2+12+3 -> 84
B3: miel
B4: Viande | C4: 36
B5: Intermarché | D5: =106+101+112+115 -> 434
A6: Habitation | B6: Loyer
B7: vanille
C8: =SUM(C2:C7) -> 38 | D8: =SUM(D2:D7) -> 518
B9: Assurance | D9: 26
B10: Impôt
B11: Eau
B12: direct énergie | D12: 181
B13: Internet | C13: 32
B14: Taxe habitation
B15: Ramonage | C15: =185 -> 185
A17: Total | C17: =SUM(C9:C16) -> 217 | D17: =SUM(D9:D16) -> 207
A18: Loisirs | B18: Restaurant | D18: 51
B19: Week-end/vacances | C19: =2138+71 -> 2209 | D19: =95+82 -> 177
B21: Livres
A22: Total | C22: =SUM(C18:C21) -> 2209 | D22: =SUM(D18:D21) -> 228
A23: Vie quotidienne | B23: pharmacie
B24: Berlioz/rats | D24: 99
B25: Sport
B26: Cadeaux
B27: Appartement | C27: 80
B28: Immo
A29: Total | C29: =sum(C23:C28) -> 80 | D29: =sum(D23:D28) -> 99
A30: Total
A31: Total Chris | D31: =C8+C17+C22+C29 -> 2544
A32: Total Alex | D32: =D8+D17+D22+D29 -> 1052
A33: Balance | D33: =(D32-D31)/2 -> -746
A35: Dettes:
A36: Chris → Alex | B36: Montant | F36: Alex → Chris | G36: Montant | I36: Balance finale (Chris->Alex) | J36: =B43-G43 -> -261
A37: Balance courante | B37: =D33 -> -746 | F37: Virement
A38: Balence précédente | B38: -721 | F38: babou | G38: 20 | I38: Synthèse
A39: appart | B39: 115 | I39: Total habitation / personne | J39: =D17/2 -> 103.5
A40: poncho | B40: 17 | I40: Total alimentation / personne | J40: =D8/2 -> 259
A41: thailande | B41: 1069 | I41: Total loisir / personne | J41: =D22/2 -> 114
A42: edf | B42: 25 | I42: Total vie quotidienne / personne | J42: =D29/2 -> 49.5
A43: Total | B43: =sum(B37:B42) -> -241 | F43: Total | G43: =sum(G37:G42) -> 20 | I43: Total commun / personne | J43: =sum(J39:J42) -> 526

Sheet juin 2024
C1: Chris | D1: Alex
A2: Alimentation | B2: marché/pain | D2: 12
B3: miel
B4: Viande | D4: 35
B5: Intermarché | D5: =119+98+100+94 -> 411
A6: Habitation | B6: Loyer
B7: vanille
C8: =SUM(C2:C7) -> 0 | D8: =SUM(D2:D7) -> 458
B9: Assurance | D9: 26
B10: Impôt
B11: Eau
B12: direct énergie | D12: 160
B13: Internet | C13: 33
B14: Taxe habitation
B15: Ramonage
A17: Total | C17: =SUM(C9:C16) -> 33 | D17: =SUM(D9:D16) -> 186
A18: Loisirs | B18: Restaurant
B19: Week-end/vacances
B21: Livres
A22: Total | C22: =SUM(C18:C21) -> 0 | D22: =SUM(D18:D21) -> 0
A23: Vie quotidienne | B23: pharmacie
B24: Berlioz/rats
B25: Sport
B26: Cadeaux | D26: 50
B27: Appartement
B28: Immo
A29: Total | C29: =sum(C23:C28) -> 0 | D29: =sum(D23:D28) -> 50
A30: Total
A31: Total Chris | D31: =C8+C17+C22+C29 -> 33
A32: Total Alex | D32: =D8+D17+D22+D29 -> 694
A33: Balance | D33: =(D32-D31)/2 -> 330.5
A35: Dettes:
A36: Chris → Alex | B36: Montant | F36: Alex → Chris | G36: Montant | I36: Balance finale (Chris->Alex) | J36: =B43-G43 -> -395.5
A37: Balance courante | B37: =D33 -> 330.5 | F37: Virement | G37: 600
A38: Balence précédente | B38: -261 | I38: Synthèse
A39: appart | B39: 115 | I39: Total habitation / personne | J39: =D17/2 -> 93
A40: pharmacie | I40: Total alimentation / personne | J40: =D8/2 -> 229
B41: 20 | I41: Total loisir / personne | J41: =D22/2 -> 0
I42: Total vie quotidienne / personne | J42: =D29/2 -> 25
A43: Total | B43: =sum(B37:B42) -> 204.5 | F43: Total | G43: =sum(G37:G42) -> 600 | I43: Total commun / personne | J43: =sum(J39:J42) -> 347

Sheet juillet 2024
C1: Chris | D1: Alex
A2: Alimentation | B2: marché/pain | C2: =20 -> 20 | D2: =8+17+3+6+2+15 -> 51
B3: miel
B4: Viande | D4: 36
B5: Intermarché | D5: =91+26+44+95+160+71 -> 487
A6: Habitation | B6: Loyer | I6: 49.96 | J6: =SUM(I6:I22) -> 310.36
I7: 29
C8: =SUM(C2:C7) -> 20 | D8: =SUM(D2:D7) -> 574 | I8: 2.6
B9: Assurance | D9: 29 | I9: 14.7
B10: Impôt | I10: 3.7
B11: Eau | I11: 2.6
B12: direct énergie | D12: 160 | I12: 5
B13: Internet | C13: 33 | I13: 24
B14: Taxe habitation | I14: 1
B15: Ramonage | I15: 94.6
I16: 24.4
A17: Total | C17: =SUM(C9:C16) -> 33 | D17: =SUM(D9:D16) -> 189 | I17: 4.9
A18: Loisirs | B18: Restaurant | D18: 67 | I18: 3.7
B19: Week-end/vacances | C19: =30+310 -> 340 | D19: =22+108+10+20+17+3+26+102+111+103 -> 522 | I19: 14.7
I20: 2.6
B21: Livres | I21: 15
A22: Total | C22: =SUM(C18:C21) -> 340 | D22: =SUM(D18:D21) -> 589 | I22: 17.9
A23: Vie quotidienne | B23: pharmacie
B24: Berlioz/rats | D24: =91+45 -> 136
B25: Sport
B26: Cadeaux | D26: =40+100 -> 140
B27: Appartement
B28: Immo
A29: Total | C29: =sum(C23:C28) -> 0 | D29: =sum(D23:D28) -> 276
A30: Total
A31: Total Chris | D31: =C8+C17+C22+C29 -> 393
A32: Total Alex | D32: =D8+D17+D22+D29 -> 1628
A33: Balance | D33: =(D32-D31)/2 -> 617.5
A35: Dettes:
A36: Chris → Alex | B36: Montant | F36: Alex → Chris | G36: Montant | I36: Balance finale (Chris->Alex) | J36: =B43-G43 -> -214.5
A37: Balance courante | B37: =D33 -> 617.5 | F37: Virement | G37: =500 -> 500
A38: Balence précédente | B38: -396 | F38: gaz | G38: 25 | I38: Synthèse
A39: appart | B39: 115 | G39: 60 | I39: Total habitation / personne | J39: =D17/2 -> 94.5
A40: pharmacie | I40: Total alimentation / personne | J40: =D8/2 -> 287
A41: pierre mylan | B41: 20 | I41: Total loisir / personne | J41: =D22/2 -> 294.5
...

Sheet août 2024
C1: Chris | D1: Alex
A2: Alimentation | B2: marché/pain | D2: =26+7+20+11 -> 64
B3: miel
B4: Viande | D4: =18+16 -> 34
B5: Intermarché | D5: =69+67+96+61+87 -> 380
A6: Habitation | B6: Loyer | I6: 49.96 | J6: =SUM(I6:I22) -> 310.36
B7: vanille | I7: 29
C8: =SUM(C2:C7) -> 0 | D8: =SUM(D2:D7) -> 478 | I8: 2.6
B9: Assurance | I9: 14.7
B10: Impôt | I10: 3.7
B11: Eau | I11: 2.6
B12: direct énergie | D12: 160 | I12: 5
B13: Internet | C13: 33 | I13: 24
B14: Taxe habitation | I14: 1
B15: Ramonage | I15: 94.6
B16: amazon abonnement annuel | D16: 70 | I16: 24.4
A17: Total | C17: =SUM(C9:C16) -> 33 | D17: =SUM(D9:D16) -> 230 | I17: 4.9
A18: Loisirs | B18: Restaurant | I18: 3.7
B19: Week-end/vacances | C19: =54+10+11 -> 75 | I19: 14.7
I20: 2.6
B21: Livres | I21: 15
A22: Total | C22: =SUM(C18:C21) -> 75 | D22: =SUM(D18:D21) -> 0 | I22: 17.9
A23: Vie quotidienne | B23: pharmacie | D23: 4
B24: Berlioz/rats
B25: Sport
B26: Cadeaux | D26: 19
B27: Appartement | D27: =17+20 -> 37
B28: Immo
A29: Total | C29: =sum(C23:C28) -> 0 | D29: =sum(D23:D28) -> 60
A30: Total
A31: Total Chris | D31: =C8+C17+C22+C29 -> 108
A32: Total Alex | D32: =D8+D17+D22+D29 -> 768
A33: Balance | D33: =(D32-D31)/2 -> 330
A35: Dettes:
A36: Chris → Alex | B36: Montant | F36: Alex → Chris | G36: Montant | I36: Balance finale (Chris->Alex) | J36: =B43-G43 -> -824
A37: Balance courante | B37: =D33 -> 330 | F37: Virement | G37: 500
A38: Balence précédente | B38: -215 | G38: 600 | I38: Synthèse
A39: appart | B39: 115 | I39: Total habitation / personne | J39: =D17/2 -> 115
A40: pharmacie | B40: 16 | I40: Total alimentation / personne | J40: =D8/2 -> 239
A41: vin Céline | B41: 30 | I41: Total loisir / personne | J41: =D22/2 -> 0
...

Sheet septembre 2024
C1: Chris | D1: Alex
A2: Alimentation | B2: marché/pain | D2: =3+25+18+13+19+18+5+7 -> 108
B3: miel
B4: Viande | D4: =29+26 -> 55
B5: Intermarché | C5: =37 -> 37 | D5: =77+117+95+100 -> 389
A6: Habitation | B6: Loyer | I6: 49.96 | J6: =SUM(I6:I22) -> 310.36
B7: vanille | I7: 29
C8: =SUM(C2:C7) -> 37 | D8: =SUM(D2:D7) -> 552 | I8: 2.6
B9: Assurance | D9: 29 | I9: 14.7
B10: Impôt | I10: 3.7
B11: Eau | I11: 2.6
B12: direct énergie | D12: 160 | I12: 5
B13: Internet | C13: =33+10 -> 43 | I13: 24
B14: Taxe habitation | I14: 1
B15: Ramonage | I15: 94.6
B16: amazon abonnement annuel | I16: 24.4
A17: Total | C17: =SUM(C9:C16) -> 43 | D17: =SUM(D9:D16) -> 189 | I17: 4.9
A18: Loisirs | B18: Restaurant | I18: 3.7
B19: Week-end/vacances | I19: 14.7
I20: 2.6
B21: Livres | I21: 15
A22: Total | C22: =SUM(C18:C21) -> 0 | D22: =SUM(D18:D21) -> 0 | I22: 17.9
A23: Vie quotidienne | B23: pharmacie | D23: 7
B24: Berlioz/rats | D24: 76
B25: Sport
B26: Cadeaux
B27: Appartement | D27: 6
B28: Immo
A29: Total | C29: =sum(C23:C28) -> 0 | D29: =sum(D23:D28) -> 89
A30: Total
A31: Total Chris | D31: =C8+C17+C22+C29 -> 80
A32: Total Alex | D32: =D8+D17+D22+D29 -> 830
A33: Balance | D33: =(D32-D31)/2 -> 375
A35: Dettes:
A36: Chris → Alex | B36: Montant | F36: Alex → Chris | G36: Montant | I36: Balance finale (Chris->Alex) | J36: =B43-G43 -> -215
A37: Balance courante | B37: =D33 -> 375 | F37: Virement
A38: Balence précédente | B38: -824 | I38: Synthèse
A39: appart | B39: 115 | I39: Total habitation / personne | J39: =D17/2 -> 94.5
A40: amazon chris | B40: 92 | I40: Total alimentation / personne | J40: =D8/2 -> 276
A41: pharma | B41: =9+18 -> 27 | I41: Total loisir / personne | J41: =D22/2 -> 0
...

Sheet octobre 2024
C1: Chris | D1: Alex
A2: Alimentation | B2: marché/pain | D2: =2+22 -> 24
B3: miel
B4: Viande | D4: 20
B5: Intermarché | C5: =42+23 -> 65 | D5: =40+84+62+75 -> 261
A6: Habitation | B6: Loyer | I6: 49.96 | J6: =SUM(I6:I22) -> 310.36
B7: vanille | I7: 29
C8: =SUM(C2:C7) -> 65 | D8: =SUM(D2:D7) -> 305 | I8: 2.6
B9: Assurance | D9: 29 | I9: 14.7
B10: Impôt | I10: 3.7
B11: Eau | I11: 2.6
B12: direct énergie | D12: 160 | I12: 5
B13: Internet | C13: =33+10 -> 43 | I13: 24
B14: Taxe habitation | I14: 1
B15: Ramonage | I15: 94.6
B16: amazon abonnement annuel | I16: 24.4
A17: Total | C17: =SUM(C9:C16) -> 43 | D17: =SUM(D9:D16) -> 189 | I17: 4.9
A18: Loisirs | B18: Restaurant | I18: 3.7
B19: Week-end/vacances | C19: 51 | D19: =30+84+76 -> 190 | I19: 14.7
I20: 2.6
B21: Livres | I21: 15
A22: Total | C22: =SUM(C18:C21) -> 51 | D22: =SUM(D18:D21) -> 190 | I22: 17.9
A23: Vie quotidienne | B23: pharmacie | D23: 30
B24: Berlioz/rats
B25: Sport
B26: Cadeaux
B27: Appartement
B28: Immo
A29: Total | C29: =sum(C23:C28) -> 0 | D29: =sum(D23:D28) -> 30
A30: Total
A31: Total Chris | D31: =C8+C17+C22+C29 -> 159
A32: Total Alex | D32: =D8+D17+D22+D29 -> 714
A33: Balance | D33: =(D32-D31)/2 -> 277.5
A35: Dettes:
A36: Chris → Alex | B36: Montant | F36: Alex → Chris | G36: Montant | I36: Balance finale (Chris->Alex) | J36: =B43-G43 -> 177.5
A37: Balance courante | B37: =D33 -> 277.5 | F37: Virement
A38: Balence précédente | B38: -215 | I38: Synthèse
A39: appart | B39: 115 | I39: Total habitation / personne | J39: =D17/2 -> 94.5
I40: Total alimentation / personne | J40: =D8/2 -> 152.5
I41: Total loisir / personne | J41: =D22/2 -> 95
...

Sheet novembre 2024
C1: Chris | D1: Alex
A2: Alimentation | B2: marché/pain | D2: =9+4+2+4+5+4+4 -> 32
B3: miel
B4: Viande | C4: 15
B5: Intermarché | C5: =33+33+24 -> 90 | D5: =125+81+53+23+64 -> 346
A7: Habitation | B7: Loyer | I7: 49.96 | J7: =SUM(I7:I23) -> 310.36
B8: vanille | I8: 29
C9: =SUM(C2:C8) -> 105 | D9: =SUM(D2:D8) -> 378 | I9: 2.6
B10: Assurance | D10: 29 | I10: 14.7
B11: Impôt | I11: 3.7
B12: Eau | I12: 2.6
B13: direct énergie | D13: 160 | I13: 5
B14: Internet | C14: =33+10 -> 43 | I14: 24
B15: Taxe habitation | C15: =1960 -> 1960 | I15: 1
B16: Ramonage | I16: 94.6
B17: amazon abonnement annuel | I17: 24.4
A18: Total | C18: =SUM(C10:C17) -> 2003 | D18: =SUM(D10:D17) -> 189 | I18: 4.9
A19: Loisirs | B19: Restaurant | C19: 156 | D19: =50+11+19+8 -> 88 | I19: 3.7
B20: Week-end/vacances | C20: =115+90+8+8+79+97+213 -> 610 | D20: =84+295 -> 379 | I20: 14.7
I21: 2.6
B22: Livres | I22: 15
A23: Total | C23: =SUM(C19:C22) -> 766 | D23: =SUM(D19:D22) -> 467 | I23: 17.9
A24: Vie quotidienne | B24: pharmacie
B25: Berlioz/rats
B26: Sport
B27: Cadeaux
B28: Appartement | D28: 57
B29: Immo
A30: Total | C30: =sum(C24:C29) -> 0 | D30: =sum(D24:D29) -> 57
A31: Total
A32: Total Chris | D32: =C9+C18+C23+C30 -> 2874
A33: Total Alex | D33: =D9+D18+D23+D30 -> 1091
A34: Balance | D34: =(D33-D32)/2 -> -891.5
A36: Dettes:
A37: Chris → Alex | B37: Montant | F37: Alex → Chris | G37: Montant | I37: Balance finale (Chris->Alex) | J37: =B44-G44 -> -674.5
A38: Balance courante | B38: =D34 -> -891.5 | F38: Virement
A39: Balence précédente | B39: 178 | F39: pharma | G39: 16 | I39: Synthèse
A40: appart | B40: 115 | G40: 60 | I40: Total habitation / personne | J40: =D18/2 -> 94.5
I41: Total alimentation / personne | J41: =D9/2 -> 189
I42: Total loisir / personne | J42: =D23/2 -> 233.5
...

Sheet décembre 2024
C1: Chris | D1: Alex
A2: Alimentation | B2: marché/pain | D2: =6+2 -> 8
B3: miel
B4: Viande | D4: =15+23+27 -> 65
B5: Intermarché | C5: =31+26+19+22 -> 98 | D5: =7+84+67+45 -> 203
A7: Habitation | B7: Loyer | I7: 49.96 | J7: =SUM(I7:I23) -> 310.36
B8: vanille | I8: 29
C9: =SUM(C2:C8) -> 98 | D9: =SUM(D2:D8) -> 276 | I9: 2.6
B10: Assurance | D10: 29 | I10: 14.7
B11: Impôt | I11: 3.7
B12: Eau | I12: 2.6
B13: direct énergie | D13: 160 | I13: 5
B14: Internet | C14: =33+10 -> 43 | I14: 24
B15: Taxe habitation | I15: 1
B16: Ramonage | I16: 94.6
B17: amazon abonnement annuel | I17: 24.4
A18: Total | C18: =SUM(C10:C17) -> 43 | D18: =SUM(D10:D17) -> 189 | I18: 4.9
A19: Loisirs | B19: Restaurant | I19: 3.7
B20: Week-end/vacances | I20: 14.7
I21: 2.6
B22: Livres | I22: 15
A23: Total | C23: =SUM(C19:C22) -> 0 | D23: =SUM(D19:D22) -> 0 | I23: 17.9
A24: Vie quotidienne | B24: pharmacie
B25: Berlioz/rats | C25: =122 -> 122
B26: Sport
B27: Cadeaux | D27: 58
B28: Appartement
B29: Immo
A30: Total | C30: =sum(C24:C29) -> 122 | D30: =sum(D24:D29) -> 58
A31: Total
A32: Total Chris | D32: =C9+C18+C23+C30 -> 263
A33: Total Alex | D33: =D9+D18+D23+D30 -> 523
A34: Balance | D34: =(D33-D32)/2 -> 130
A36: Dettes:
A37: Chris → Alex | B37: Montant | F37: Alex → Chris | G37: Montant | I37: Balance finale (Chris->Alex) | J37: =B44-G44 -> -424
A38: Balance courante | B38: =D34 -> 130 | F38: Virement
A39: Balence précédente | B39: -675 | F39: pharma | I39: Synthèse
A40: appart | B40: 115 | I40: Total habitation / personne | J40: =D18/2 -> 94.5
A41: pharmacie | B41: 6 | I41: Total alimentation / personne | J41: =D9/2 -> 138
I42: Total loisir / personne | J42: =D23/2 -> 0
...

Sheet janvier 2025
C1: Chris | D1: Alex
A2: Alimentation | B2: marché/pain | D2: =7+2+5+3+13+7 -> 37
B3: miel
B4: Viande | D4: =14+37+23 -> 74
B5: Intermarché | C5: =22+21+24+21 -> 88 | D5: =67+66+61+73+52+49 -> 368
A7: Habitation | B7: Loyer | I7: 49.96 | J7: =SUM(I7:I23) -> 310.36
B8: vanille | I8: 29
C9: =SUM(C2:C8) -> 88 | D9: =SUM(D2:D8) -> 479 | I9: 2.6
B10: Assurance | D10: =29+427 -> 456 | I10: 14.7
B11: Impôt | I11: 3.7
B12: Eau | I12: 2.6
B13: direct énergie | D13: 160 | I13: 5
B14: Internet | C14: =33 -> 33 | I14: 24
B15: Taxe habitation | I15: 1
B16: Ramonage | I16: 94.6
B17: amazon abonnement annuel | I17: 24.4
A18: Total | C18: =SUM(C10:C17) -> 33 | D18: =SUM(D10:D17) -> 616 | I18: 4.9
A19: Loisirs | B19: Restaurant | C19: =63+46+7 -> 116 | I19: 3.7
B20: Week-end/vacances | C20: =99+84+50 +11 -> 244 | D20: =20+110+28+28 -> 186 | I20: 14.7
I21: 2.6
B22: Livres | I22: 15
A23: Total | C23: =SUM(C19:C22) -> 360 | D23: =SUM(D19:D22) -> 186 | I23: 17.9
A24: Vie quotidienne | B24: pharmacie | D24: 11
B25: Berlioz/rats
B26: Sport
B27: Cadeaux
B28: Appartement
B29: Immo
A30: Total | C30: =sum(C24:C29) -> 0 | D30: =sum(D24:D29) -> 11
A31: Total
A32: Total Chris | D32: =C9+C18+C23+C30 -> 481
A33: Total Alex | D33: =D9+D18+D23+D30 -> 1292
A34: Balance | D34: =(D33-D32)/2 -> 405.5
A36: Dettes:
A37: Chris → Alex | B37: Montant | F37: Alex → Chris | G37: Montant | I37: Balance finale (Chris->Alex) | J37: =B44-G44 -> -344.5
A38: Balance courante | B38: =D34 -> 405.5 | F38: Virement | G38: 400
A39: Balence précédente | B39: -424 | F39: Virement babou | G39: 58 | I39: Synthèse
A40: appart | B40: 115 | I40: Total habitation / personne | J40: =D18/2 -> 308
A41: pharma | B41: 17 | I41: Total alimentation / personne | J41: =D9/2 -> 239.5
I42: Total loisir / personne | J42: =D23/2 -> 93
...

Sheet février 2025
A1: Catégorie | B1: Sous catégorie | C1: Chris | D1: Alex
A2: Alimentation | B2: marché/pain | D2: =5+6+15+9 -> 35
B3: miel
B4: Viande
B5: Intermarché | C5: =20+22+11+14 -> 67 | D5: 73
A7: Habitation | B7: Loyer | H7: 49.96 | I7: =SUM(H7:H23) -> 310.36 | K7: -5.4
B8: vanille | H8: 29 | K8: -14.6
C9: =SUM(C2:C8) -> 67 | D9: =SUM(D2:D8) -> 108 | H9: 2.6 | K9: -7.4
B10: Assurance | D10: 29 | H10: 14.7 | K10: -7
B11: Impôt | D11: 251 | H11: 3.7 | K11: -20.8
B12: Eau | H12: 2.6 | K12: -10
B13: direct énergie | D13: 160 | H13: 5 | K13: -1.5
B14: Internet | C14: =33 -> 33 | H14: 24 | K14: -1.5
B15: Taxe habitation | H15: 1 | K15: -38.57
B16: Ramonage | H16: 94.6 | K16: -577.18
B17: amazon abonnement annuel | H17: 24.4 | K17: -1.5
A18: Total | C18: =SUM(C10:C17) -> 33 | D18: =SUM(D10:D17) -> 440 | H18: 4.9 | K18: -11.3
A19: Loisirs | B19: Restaurant | C19: =51 -> 51 | H19: 3.7 | K19: -16.2
B20: Week-end/vacances | C20: =-sum(K7:K25) -> 801.85 | D20: 68 | H20: 14.7 | K20: -10.01
H21: 2.6 | K21: -49.99
B22: Livres | H22: 15 | K22: -1.5
A23: Total | C23: =SUM(C19:C22) -> 852.85 | D23: =SUM(D19:D22) -> 68 | H23: 17.9 | K23: -14.6
A24: Vie quotidienne | B24: pharmacie | K24: -5.4
B25: Berlioz/rats | D25: =90+26 -> 116 | K25: -7.4
B26: Sport
B27: Cadeaux
B28: Appartement
B29: Immo
A30: Total | C30: =sum(C24:C29) -> 0 | D30: =sum(D24:D29) -> 116
A31: Total
A32: Total Chris | D32: =C9+C18+C23+C30 -> 952.85
A33: Total Alex | D33: =D9+D18+D23+D30 -> 732
A34: Balance | D34: =(D33-D32)/2 -> -110.425
A36: Dettes:
A38: Chris → Alex | B38: Montant | E38: Alex → Chris | F38: Montant | H38: Balance finale (Chris->Alex) | I38: =B45-F45 -> -851.425
A39: Balance courante | B39: =D34 -> -110.425 | E39: Virement | F39: 500
A40: Balence précédente | B40: -356 | H40: Synthèse
A41: appart | B41: 115 | H41: Total habitation / personne | I41: =D18/2 -> 220
H42: Total alimentation / personne | I42: =D9/2 -> 54
H43: Total loisir / personne | I43: =D23/2 -> 34
...

Sheet mars 2025
A1: Catégorie | B1: Sous catégorie | C1: Chris | D1: Alex
A2: Alimentation | B2: marché/pain | D2: =13+8+6+7 -> 34
B3: miel
B4: Viande | D4: =40+16+25 -> 81
B5: Intermarché | C5: =22+23+30 -> 75 | D5: =110+83+84+88+91 -> 456
A7: Habitation | B7: Loyer | H7: 49.96 | I7: =SUM(H7:H23) -> 310.36 | K7: -5.4
B8: vanille | H8: 29 | K8: -14.6
C9: =SUM(C2:C8) -> 75 | D9: =SUM(D2:D8) -> 571 | H9: 2.6 | K9: -7.4
B10: Assurance | D10: 29 | H10: 14.7 | K10: -7
B11: Impôt | H11: 3.7 | K11: -20.8
B12: Eau | H12: 2.6 | K12: -10
B13: direct énergie | D13: 160 | H13: 5 | K13: -1.5
B14: Internet | C14: =33 -> 33 | H14: 24 | K14: -1.5
B15: Taxe habitation | H15: 1 | K15: -38.57
B16: Ramonage | H16: 94.6 | K16: -577.18
B17: amazon abonnement annuel | H17: 24.4 | K17: -1.5
A18: Total | C18: =SUM(C10:C17) -> 33 | D18: =SUM(D10:D17) -> 189 | H18: 4.9 | K18: -11.3
A19: Loisirs | B19: Restaurant | C19: =59 -> 59 | H19: 3.7 | K19: -16.2
B20: Week-end/vacances | D20: 285 | H20: 14.7 | K20: -10.01
H21: 2.6 | K21: -49.99
B22: Livres | H22: 15 | K22: -1.5
A23: Total | C23: =SUM(C19:C22) -> 59 | D23: =SUM(D19:D22) -> 285 | H23: 17.9 | K23: -14.6
A24: Vie quotidienne | B24: pharmacie | K24: -5.4
B25: Berlioz/rats | D25: 61 | K25: -7.4
B26: Sport
B27: Cadeaux
B28: Appartement | C28: 20
B29: Immo
A30: Total | C30: =sum(C24:C29) -> 20 | D30: =sum(D24:D29) -> 61
A31: Total
A32: Total Chris | D32: =C9+C18+C23+C30 -> 187
A33: Total Alex | D33: =D9+D18+D23+D30 -> 1106
A34: Balance | D34: =(D33-D32)/2 -> 459.5
A36: Dettes:
A38: Chris → Alex | B38: Montant | E38: Alex → Chris | F38: Montant | H38: Balance finale (Chris->Alex) | I38: =B45-F45 -> -276.5
A39: Balance courante | B39: =D34 -> 459.5 | E39: Virement
A40: Balence précédente | B40: -851 | H40: Synthèse
A41: appart | B41: 115 | H41: Total habitation / personne | I41: =D18/2 -> 94.5
H42: Total alimentation / personne | I42: =D9/2 -> 285.5
H43: Total loisir / personne | I43: =D23/2 -> 142.5
...

Sheet avril 2025
A1: Catégorie | B1: Sous catégorie | C1: Chris | D1: Alex
A2: Alimentation | B2: marché/pain | D2: =9+14+4+14+8 -> 49
B3: miel
B4: Viande | D4: =22+42+3 -> 67
B5: Intermarché | C5: =20+28+9+19+6+27+20 -> 129 | D5: =82+107+55+54 -> 298
A7: Habitation | B7: Loyer | H7: 49.96 | I7: =SUM(H7:H23) -> 310.36 | K7: -5.4
B8: vanille | H8: 29 | K8: -14.6
C9: =SUM(C2:C8) -> 129 | D9: =SUM(D2:D8) -> 414 | H9: 2.6 | K9: -7.4
B10: Assurance | D10: 29 | H10: 14.7 | K10: -7
B11: Impôt | H11: 3.7 | K11: -20.8
B12: Eau | H12: 2.6 | K12: -10
B13: direct énergie | D13: 160 | H13: 5 | K13: -1.5
B14: Internet | C14: =33 -> 33 | H14: 24 | K14: -1.5
B15: Taxe habitation | H15: 1 | K15: -38.57
B16: Ramonage | H16: 94.6 | K16: -577.18
B17: amazon abonnement annuel | H17: 24.4 | K17: -1.5
A18: Total | C18: =SUM(C10:C17) -> 33 | D18: =SUM(D10:D17) -> 189 | H18: 4.9 | K18: -11.3
A19: Loisirs | B19: Restaurant | H19: 3.7 | K19: -16.2
B20: Week-end/vacances | D20: 950 | H20: 14.7 | K20: -10.01
H21: 2.6 | K21: -49.99
B22: Livres | H22: 15 | K22: -1.5
A23: Total | C23: =SUM(C19:C22) -> 0 | D23: =SUM(D19:D22) -> 950 | H23: 17.9 | K23: -14.6
A24: Vie quotidienne | B24: pharmacie | K24: -5.4
B25: Berlioz/rats | C25: =92+5 -> 97 | K25: -7.4
B26: Sport
B27: Cadeaux | D27: =59+70 -> 129
B28: Appartement | C28: 26 | D28: 70
B29: Immo
A30: Total | C30: =sum(C24:C29) -> 123 | D30: =sum(D24:D29) -> 199
A31: Total
A32: Total Chris | D32: =C9+C18+C23+C30 -> 285
A33: Total Alex | D33: =D9+D18+D23+D30 -> 1752
A34: Balance | D34: =(D33-D32)/2 -> 733.5
A36: Dettes:
A38: Chris → Alex | B38: Montant | E38: Alex → Chris | F38: Montant | H38: Balance finale (Chris->Alex) | I38: =B45-F45 -> -378.5
A39: Balance courante | B39: =D34 -> 733.5 | E39: Virement | F39: 900
A40: Balence précédente | B40: -277 | E40: total energie | F40: 45 | H40: Synthèse
A41: appart | B41: 115 | F41: 5 | H41: Total habitation / personne | I41: =D18/2 -> 94.5
H42: Total alimentation / personne | I42: =D9/2 -> 207
H43: Total loisir / personne | I43: =D23/2 -> 475
...

Sheet mai 2025
A1: Catégorie | B1: Sous catégorie | C1: Chris | D1: Alex
A2: Alimentation | B2: marché/pain | D2: =3+15+5 -> 23
B3: miel
B4: Viande | D4: 35
B5: Intermarché | C5: =39+25+33 -> 97 | D5: =100+62+69+46 -> 277
H6: Lozere Chris | J6: Info autoroute/carburant
A7: Habitation | B7: Loyer | J7: 33.71
B8: vanille | J8: 23.42
C9: =SUM(C2:C8) -> 97 | D9: =SUM(D2:D8) -> 335 | H9: 1.5 | J9: 52
B10: Assurance | D10: 29 | H10: 38.91 | J10: 5
B11: Impôt | H11: 32 | J11: 2.4
B12: Eau | H12: 21 | J12: 3.4
B13: direct énergie | D13: 137 | H13: 12.34 | J13: 14.8
B14: Internet | C14: =33 -> 33 | H14: 110.61 | J14: 11.2
B15: Taxe habitation
B16: Ramonage | D16: 185
B17: amazon abonnement annuel | C17: 8
A18: Total | C18: =SUM(C10:C17) -> 41 | D18: =SUM(D10:D17) -> 351
A19: Loisirs | B19: Restaurant
B20: Week-end/vacances | C20: =216+20 -> 236 | D20: =120+5+121 -> 246
B22: Livres
A23: Total | C23: =SUM(C19:C22) -> 236 | D23: =SUM(D19:D22) -> 246
A24: Vie quotidienne | B24: pharmacie | D24: 6
B25: Berlioz/rats
B26: Sport
B27: Cadeaux | C27: 50
B28: Appartement
B29: Immo
A30: Total | C30: =sum(C24:C29) -> 50 | D30: =sum(D24:D29) -> 6
A31: Total
A32: Total Chris | D32: =C9+C18+C23+C30 -> 424
A33: Total Alex | D33: =D9+D18+D23+D30 -> 938
A34: Balance | D34: =(D33-D32)/2 -> 257
A36: Dettes:
A38: Chris → Alex | B38: Montant | E38: Alex → Chris | F38: Montant | H38: Balance finale (Chris->Alex) | I38: =B45-F45 -> -329
A39: Balance courante | B39: =D34 -> 257 | E39: Virement | F39: 300
A40: Balence précédente | B40: -379 | E40: oscaro | F40: 22 | H40: Synthèse
A41: appart | B41: 115 | H41: Total habitation / personne | I41: =D18/2 -> 175.5
H42: Total alimentation / personne | I42: =D9/2 -> 167.5
H43: Total loisir / personne | I43: =D23/2 -> 123
...

Sheet juin 2025
A1: Catégorie | B1: Sous catégorie | C1: Chris | D1: Alex
A2: Alimentation | B2: marché/pain | D2: =3+5 -> 8
B3: miel
B4: Viande | D4: =29+15+18+40 -> 102
B5: Intermarché | C5: =25+22+32 -> 79 | D5: =43+54+61+18+83 -> 259
H6: Lozere Chris | J6: Info autoroute/carburant
A7: Habitation | B7: Loyer | J7: 33.71
B8: vanille | J8: 23.42
C9: =SUM(C2:C8) -> 79 | D9: =SUM(D2:D8) -> 369 | H9: 1.5 | J9: 52
B10: Assurance | D10: 29 | H10: 38.91 | J10: 5
B11: Impôt | H11: 32 | J11: 2.4
B12: Eau | H12: 21 | J12: 3.4
B13: direct énergie | D13: 137 | H13: 12.34 | J13: 14.8
B14: Internet | C14: =33 -> 33 | H14: 110.61 | J14: 11.2
B15: Taxe habitation
B16: Ramonage
B17: amazon abonnement annuel
A18: Total | C18: =SUM(C10:C17) -> 33 | D18: =SUM(D10:D17) -> 166
A19: Loisirs | B19: Restaurant | C19: =31 -> 31 | D19: 52
B20: Week-end/vacances | C20: =86+7+26+13 -> 132 | D20: =11+39 -> 50
B21: ekosport | D21: 284
B22: Livres
A23: Total | C23: =SUM(C19:C22) -> 163 | D23: =SUM(D19:D22) -> 386
A24: Vie quotidienne | B24: pharmacie
B25: Berlioz/rats | D25: =30+20 -> 50
B26: Sport
B27: Cadeaux
B28: Appartement
B29: Immo
A30: Total | C30: =sum(C24:C29) -> 0 | D30: =sum(D24:D29) -> 50
A31: Total
A32: Total Chris | D32: =C9+C18+C23+C30 -> 275
A33: Total Alex | D33: =D9+D18+D23+D30 -> 971
A34: Balance | D34: =(D33-D32)/2 -> 348
A36: Dettes:
A38: Chris → Alex | B38: Montant | E38: Alex → Chris | F38: Montant | H38: Balance finale (Chris->Alex) | I38: =B45-F45 -> -320
A39: Balance courante | B39: =D34 -> 348 | E39: Virement | F39: 500
A40: Balence précédente | B40: -313 | H40: Synthèse
A41: appart | B41: 115 | H41: Total habitation / personne | I41: =D18/2 -> 83
B42: 30 | H42: Total alimentation / personne | I42: =D9/2 -> 184.5
...

Sheet juillet 2025
A1: Catégorie | B1: Sous catégorie | C1: Chris | D1: Alex
A2: Alimentation | B2: marché/pain | D2: =5+3+18+10 -> 36
B3: miel
B4: Viande | D4: 30
B5: Intermarché | C5: =27+23+19 -> 69 | D5: =64+57+60+80 -> 261
H6: Lozere Chris | J6: Info autoroute/carburant
A7: Habitation | B7: Loyer | J7: 33.71
B8: vanille | J8: 23.42
C9: =SUM(C2:C8) -> 69 | D9: =SUM(D2:D8) -> 327 | H9: 1.5 | J9: 52
B10: Assurance | D10: 29 | H10: 38.91 | J10: 5
B11: Impôt | H11: 32 | J11: 2.4
B12: Eau | H12: 21 | J12: 3.4
B13: direct énergie | D13: 137 | H13: 12.34 | J13: 14.8
B14: Internet | C14: =33 -> 33 | H14: 110.61 | J14: 11.2
B15: Taxe habitation
B16: Ramonage
B17: amazon abonnement annuel | D17: 70
A18: Total | C18: =SUM(C10:C17) -> 33 | D18: =SUM(D10:D17) -> 236
A19: Loisirs | B19: Restaurant
B20: Week-end/vacances | C20: =23+20+10+40 -> 93 | D20: =7+20+30+20+142+6 -> 225
B22: Livres
A23: Total | C23: =SUM(C19:C22) -> 93 | D23: =SUM(D19:D22) -> 225
A24: Vie quotidienne | B24: pharmacie
B25: Berlioz/rats | D25: =17+62 -> 79
B26: Sport
B27: Cadeaux | D27: 30
B28: Appartement | D28: 30
B29: Immo
A30: Total | C30: =sum(C24:C29) -> 0 | D30: =sum(D24:D29) -> 139
A31: Total
A32: Total Chris | D32: =C9+C18+C23+C30 -> 195
A33: Total Alex | D33: =D9+D18+D23+D30 -> 927
A34: Balance | D34: =(D33-D32)/2 -> 366
A36: Dettes:
A38: Chris → Alex | B38: Montant | E38: Alex → Chris | F38: Montant | H38: Balance finale (Chris->Alex) | I38: =B45-F45 -> -722
A39: Balance courante | B39: =D34 -> 366 | E39: Virement | F39: 500
A40: Balence précédente | B40: -320 | E40: Egypte | F40: 500 | H40: Synthèse
A41: appart | B41: 115 | H41: Total habitation / personne | I41: =D18/2 -> 118
A42: sac à viande | B42: =26+11 -> 37 | H42: Total alimentation / personne | I42: =D9/2 -> 163.5
A43: refuge vence | B43: 30 | H43: Total loisir / personne | I43: =D23/2 -> 112.5
...

Sheet août 2025
A1: Catégorie | B1: Sous catégorie | C1: Chris | D1: Alex
A2: Alimentation | B2: marché/pain | D2: =11+14 -> 25
B3: miel
B4: Viande | D4: 25
B5: Intermarché | C5: =18+12+18+29 -> 77 | D5: =45+77+45 -> 167
A7: Habitation | B7: Loyer | I7: 4.5
I8: 13.6
C9: =SUM(C2:C8) -> 77 | D9: =SUM(D2:D8) -> 217 | I9: 38.4
B10: Assurance | D10: 29 | I10: 10.3
B11: Impôt | I11: 33
B12: Eau | I12: 12.5
B13: direct énergie | D13: 137 | I13: 2.6
B14: Internet | C14: =33 -> 33 | I14: 31.7
B15: Taxe habitation | I15: 16.3
B16: Ramonage | I16: 43.1
B17: amazon abonnement annuel | I17: 44.5
A18: Total | C18: =SUM(C10:C17) -> 33 | D18: =SUM(D10:D17) -> 166 | I18: 23.8
A19: Loisirs | B19: Restaurant | I19: 35
B20: Week-end/vacances | C20: =50+92+317+I31+37 -> 997.8 | D20: =50+70+454+121 -> 695 | I20: 15.8
I21: 13.6
B22: Livres | I22: 33.3
A23: Total | C23: =SUM(C19:C22) -> 997.8 | D23: =SUM(D19:D22) -> 695 | I23: 10.3
A24: Vie quotidienne | B24: pharmacie | I24: 17
B25: Berlioz/rats | D25: =31+60 -> 91 | I25: 10.4
B26: Sport | I26: 21
B27: Cadeaux | D27: 52 | I27: 34.5
B28: Appartement | C28: =904+28 -> 932 | D28: 70 | I28: 2.6
B29: Immo | I29: 16.3
A30: Total | C30: =sum(C24:C29) -> 932 | D30: =sum(D24:D29) -> 213 | I30: 17.7
A31: Total | I31: =SUM(I7:I30) -> 501.8
A32: Total Chris | D32: =C9+C18+C23+C30 -> 2039.8
A33: Total Alex | D33: =D9+D18+D23+D30 -> 1291
A34: Balance | D34: =(D33-D32)/2 -> -374.4
A36: Dettes:
A38: Chris → Alex | B38: Montant | E38: Alex → Chris | F38: Montant | H38: Balance finale (Chris->Alex) | I38: =B45-F45 -> -981.4
A39: Balance courante | B39: =D34 -> -374.4 | E39: Virement
A40: Balence précédente | B40: -722 | H40: Synthèse
A41: appart | B41: 115 | H41: Total habitation / personne | I41: =D18/2 -> 83
H42: Total alimentation / personne | I42: =D9/2 -> 108.5
H43: Total loisir / personne | I43: =D23/2 -> 347.5
...

Sheet septembre 2025
A1: Catégorie | B1: Sous catégorie | C1: Chris | D1: Alex
A2: Alimentation | B2: marché/pain | D2: 2
B3: miel
B4: Viande | D4: 64
B5: Intermarché | C5: =4+7+21+9+21+25 -> 87 | D5: =63+44+6+52+56 -> 221
A7: Habitation | B7: Loyer | I7: 4.5
I8: 13.6
C9: =SUM(C2:C8) -> 87 | D9: =SUM(D2:D8) -> 287 | I9: 38.4
B10: Assurance | D10: 31 | I10: 10.3
B11: Impôt | I11: 33
B12: Eau | I12: 12.5
B13: direct énergie | D13: 137 | I13: 2.6
B14: Internet | C14: =33 -> 33 | I14: 31.7
B15: Taxe habitation | I15: 16.3
B16: Ramonage | I16: 43.1
B17: amazon abonnement annuel | I17: 44.5
A18: Total | C18: =SUM(C10:C17) -> 33 | D18: =SUM(D10:D17) -> 168 | I18: 23.8
A19: Loisirs | B19: Restaurant | C19: 50 | I19: 35
B20: Week-end/vacances | C20: =66+20+80 -> 166 | D20: =145 -> 145 | I20: 15.8
I21: 13.6
B22: Livres | I22: 33.3
A23: Total | C23: =SUM(C19:C22) -> 216 | D23: =SUM(D19:D22) -> 145 | I23: 10.3
A24: Vie quotidienne | B24: pharmacie | I24: 17
B25: Berlioz/rats | D25: 61 | I25: 10.4
B26: Sport | I26: 21
B27: Cadeaux | I27: 34.5
B28: Appartement | C28: =745 -> 745 | D28: 149 | I28: 2.6
B29: Immo | I29: 16.3
A30: Total | C30: =sum(C24:C29) -> 745 | D30: =sum(D24:D29) -> 210 | I30: 17.7
A31: Total | I31: =SUM(I7:I30) -> 501.8
A32: Total Chris | D32: =C9+C18+C23+C30 -> 1081
A33: Total Alex | D33: =D9+D18+D23+D30 -> 810
A34: Balance | D34: =(D33-D32)/2 -> -135.5
A36: Dettes:
A38: Chris → Alex | B38: Montant | E38: Alex → Chris | F38: Montant | H38: Balance finale (Chris->Alex) | I38: =B45-F45 -> -386.5
A39: Balance courante | B39: =D34 -> -135.5 | E39: Virement
A40: Balence précédente | B40: -981 | E40: Berroca | F40: =19 -> 19 | H40: Synthèse
A41: appart | B41: 115 | E41: Porquerolles | F41: 143 | H41: Total habitation / personne | I41: =D18/2 -> 84
A42: but | B42: 397 | F42: 9 | H42: Total alimentation / personne | I42: =D9/2 -> 143.5
A43: babou | B43: 400 | E43: mariage | F43: 20 | H43: Total loisir / personne | I43: =D23/2 -> 72.5
...

Sheet octobre 2025
A1: Catégorie | B1: Sous catégorie | C1: Chris | D1: Alex
A2: Alimentation | B2: marché/pain | D2: =5+5+15 -> 25
B3: miel
B4: Viande | D4: 67
B5: Intermarché | C5: =15+21+29 -> 65 | D5: =69+101 -> 170
A7: Habitation | B7: Loyer | I7: 4.5
I8: 13.6
C9: =SUM(C2:C8) -> 65 | D9: =SUM(D2:D8) -> 262 | I9: 38.4
B10: Assurance | D10: 31 | I10: 10.3
B11: Impôt | I11: 33
B12: Eau | I12: 12.5
B13: direct énergie | D13: 137 | I13: 2.6
B14: Internet | C14: =33 -> 33 | D14: 6 | I14: 31.7
B15: Taxe habitation | C15: =2007 -> 2007 | I15: 16.3
B16: Ramonage | I16: 43.1
B17: amazon abonnement annuel | I17: 44.5
A18: Total | C18: =SUM(C10:C17) -> 2040 | D18: =SUM(D10:D17) -> 174 | I18: 23.8
A19: Loisirs | B19: Restaurant | I19: 35
B20: Week-end/vacances | C20: =78+51+15+20 -> 164 | D20: =30+43+59+107+19 -> 258 | I20: 15.8
I21: 13.6
B22: Livres | I22: 33.3
A23: Total | C23: =SUM(C19:C22) -> 164 | D23: =SUM(D19:D22) -> 258 | I23: 10.3
A24: Vie quotidienne | B24: pharmacie | I24: 17
B25: Berlioz/rats | D25: =60+62 -> 122 | I25: 10.4
B26: Sport | I26: 21
B27: Cadeaux | I27: 34.5
B28: Appartement | I28: 2.6
B29: Immo | I29: 16.3
A30: Total | C30: =sum(C24:C29) -> 0 | D30: =sum(D24:D29) -> 122 | I30: 17.7
A31: Total | I31: =SUM(I7:I30) -> 501.8
A32: Total Chris | D32: =C9+C18+C23+C30 -> 2269
A33: Total Alex | D33: =D9+D18+D23+D30 -> 816
A34: Balance | D34: =(D33-D32)/2 -> -726.5
A36: Dettes:
A38: Chris → Alex | B38: Montant | E38: Alex → Chris | F38: Montant | H38: Balance finale (Chris->Alex) | I38: =B45-F45 -> -1219.5
A39: Balance courante | B39: =D34 -> -726.5 | E39: Virement | F39: 300
A40: Balence précédente | B40: -387 | E40: axa | F40: 40
A41: appart | B41: 115
A42: darty | B42: =5 -> 5
B43: 7
...

Sheet novembre 2025
A1: Catégorie | B1: Sous catégorie | C1: Chris | D1: Alex
A2: Alimentation | B2: marché/pain | D2: =11+3+12+9+2+8 -> 45
B3: miel
B4: Viande | D4: =37+56+37 -> 130
B5: Intermarché | C5: =24+35+28+29 -> 116 | D5: =61+66+61+68+62 -> 318
A7: Habitation | B7: Loyer | I7: 4.5
I8: 13.6
C9: =SUM(C2:C8) -> 116 | D9: =SUM(D2:D8) -> 493 | I9: 38.4
B10: Assurance | D10: 31 | I10: 10.3
B11: Impôt | I11: 33
B12: Eau | D12: 115 | I12: 12.5
B13: direct énergie | D13: 137 | I13: 2.6
B14: Internet | C14: =33 -> 33 | I14: 31.7
B15: Taxe habitation | I15: 16.3
B16: Ramonage | I16: 43.1
B17: amazon abonnement annuel | D17: 3 | I17: 44.5
A18: Total | C18: =SUM(C10:C17) -> 33 | D18: =SUM(D10:D17) -> 286 | I18: 23.8
A19: Loisirs | B19: Restaurant | C19: 48 | I19: 35
B20: Week-end/vacances | C20: =28 -> 28 | D20: 30 | I20: 15.8
I21: 13.6
B22: Livres | I22: 33.3
A23: Total | C23: =SUM(C19:C22) -> 76 | D23: =SUM(D19:D22) -> 30 | I23: 10.3
A24: Vie quotidienne | B24: pharmacie | I24: 17
B25: Berlioz/rats | D25: 30 | I25: 10.4
B26: Sport | I26: 21
B27: Cadeaux | D27: 16 | I27: 34.5
B28: Appartement | D28: =36+11 -> 47 | I28: 2.6
B29: Immo | I29: 16.3
A30: Total | C30: =sum(C24:C29) -> 0 | D30: =sum(D24:D29) -> 93 | I30: 17.7
A31: Total | I31: =SUM(I7:I30) -> 501.8
A32: Total Chris | D32: =C9+C18+C23+C30 -> 225
A33: Total Alex | D33: =D9+D18+D23+D30 -> 902
A34: Balance | D34: =(D33-D32)/2 -> 338.5
A36: Dettes:
A38: Chris → Alex | B38: Montant | E38: Alex → Chris | F38: Montant | H38: Balance finale (Chris->Alex) | I38: =B45-F45 -> -558.5
A39: Balance courante | B39: =D34 -> 338.5 | E39: Virement
A40: Balence précédente | B40: -1220 | F40: 12
A41: appart | B41: 115
A42: espece | B42: 220
A45: Total | B45: =sum(B39:B44) -> -546.5 | E45: Total | F45: =sum(F39:F44) -> 12

Sheet décembre 2025
A1: Catégorie | B1: Sous catégorie | C1: Chris | D1: Alex
A2: Alimentation | B2: marché/pain | D2: =4+10+8+10 -> 32
B3: miel
B4: Viande | D4: 40
B5: Intermarché | C5: =27+15+25 -> 67 | D5: =46+52+48+6+84 -> 236
A7: Habitation | B7: Loyer | I7: 4.5
I8: 13.6
C9: =SUM(C2:C8) -> 67 | D9: =SUM(D2:D8) -> 308 | I9: 38.4
B10: Assurance | D10: 31 | I10: 10.3
B11: Impôt | I11: 33
B12: Eau | D12: 115 | I12: 12.5
B13: direct énergie | I13: 2.6
B14: Internet | C14: =33 -> 33 | I14: 31.7
B15: Taxe habitation | I15: 16.3
B16: Ramonage | I16: 43.1
B17: amazon abonnement annuel | D17: 2 | I17: 44.5
A18: Total | C18: =SUM(C10:C17) -> 33 | D18: =SUM(D10:D17) -> 148 | I18: 23.8
A19: Loisirs | B19: Restaurant | I19: 35
B20: Week-end/vacances | C20: =1200+50 -> 1250 | D20: =40+213+13 -> 266 | I20: 15.8
I21: 13.6
B22: Livres | I22: 33.3
A23: Total | C23: =SUM(C19:C22) -> 1250 | D23: =SUM(D19:D22) -> 266 | I23: 10.3
A24: Vie quotidienne | B24: pharmacie | I24: 17
B25: Berlioz/rats | D25: 30 | I25: 10.4
B26: Sport | I26: 21
B27: Cadeaux | D27: 58 | I27: 34.5
B28: Appartement | I28: 2.6
B29: Immo | I29: 16.3
A30: Total | C30: =sum(C24:C29) -> 0 | D30: =sum(D24:D29) -> 88 | I30: 17.7
A31: Total | I31: =SUM(I7:I30) -> 501.8
A32: Total Chris | D32: =C9+C18+C23+C30 -> 1350
A33: Total Alex | D33: =D9+D18+D23+D30 -> 810
A34: Balance | D34: =(D33-D32)/2 -> -270
A36: Dettes:
A38: Chris → Alex | B38: Montant | E38: Alex → Chris | F38: Montant | H38: Balance finale (Chris->Alex) | I38: =B45-F45 -> -656
A39: Balance courante | B39: =D34 -> -270 | E39: Virement
A40: Balence précédente | B40: -559
A41: appart | B41: 115
A42: pharma | B42: 11
A43: Noel mylan | B43: 47
...

Sheet janvier 2026
A1: Catégorie | B1: Sous catégorie | C1: Chris | D1: Alex
A2: Alimentation | B2: marché/pain | C2: =5+9+27 -> 41 | D2: =19+13 -> 32
B3: miel
B4: Viande | D4: 66
B5: Intermarché | C5: =18+25+36+40 -> 119 | D5: =60+9+27+91+69+10+79 -> 345
A7: Habitation | B7: Loyer | I7: 4.5
I8: 13.6
C9: =SUM(C2:C8) -> 160 | D9: =SUM(D2:D8) -> 443 | I9: 38.4
B10: Assurance | D10: =31+444 -> 475 | I10: 10.3
B11: Impôt | I11: 33
B12: Eau | D12: 115 | I12: 12.5
B13: direct énergie | I13: 2.6
B14: Internet | C14: =33 -> 33 | I14: 31.7
B15: Taxe habitation | I15: 16.3
B16: Ramonage | I16: 43.1
B17: amazon abonnement annuel | I17: 44.5
A18: Total | C18: =SUM(C10:C17) -> 33 | D18: =SUM(D10:D17) -> 590 | I18: 23.8
A19: Loisirs | B19: Restaurant | I19: 35
B20: Week-end/vacances | C20: =90 -> 90 | I20: 15.8
I21: 13.6
B22: Livres | I22: 33.3
A23: Total | C23: =SUM(C19:C22) -> 90 | D23: =SUM(D19:D22) -> 0 | I23: 10.3
A24: Vie quotidienne | B24: pharmacie | I24: 17
B25: Berlioz/rats | D25: 30 | I25: 10.4
B26: Sport | I26: 21
B27: Cadeaux | I27: 34.5
B28: Appartement | I28: 2.6
B29: Immo | I29: 16.3
A30: Total | C30: =sum(C24:C29) -> 0 | D30: =sum(D24:D29) -> 30 | I30: 17.7
A31: Total | I31: =SUM(I7:I30) -> 501.8
A32: Total Chris | D32: =C9+C18+C23+C30 -> 283
A33: Total Alex | D33: =D9+D18+D23+D30 -> 1063
A34: Balance | D34: =(D33-D32)/2 -> 390
A36: Dettes:
A38: Chris → Alex | B38: Montant | E38: Alex → Chris | F38: Montant | H38: Balance finale (Chris->Alex) | I38: =B45-F45 -> -27
A39: Balance courante | B39: =D34 -> 390 | E39: Virement
A40: Balence précédente | B40: -656 | E40: pharmacie | F40: =30+9 -> 39
A41: appart | B41: 115
A42: pharma | B42: 12
A43: anniversaire | B43: 136
...

Sheet fév 2026
A1: Catégorie | B1: Sous catégorie | C1: Chris | D1: Alex
A2: Alimentation | B2: marché/pain | D2: 4
B3: miel
B4: Viande | D4: 15
B5: Intermarché | D5: =38+63+60 -> 161
A7: Habitation | B7: Loyer | I7: 4.5
I8: 13.6
C9: =SUM(C2:C8) -> 0 | D9: =SUM(D2:D8) -> 180 | I9: 38.4
B10: Assurance | D10: 31 | I10: 10.3
B11: Impôt | I11: 33
B12: Eau | D12: 115 | I12: 12.5
B13: direct énergie | I13: 2.6
B14: Internet | C14: =33 -> 33 | I14: 31.7
B15: Taxe habitation | I15: 16.3
B16: Ramonage | I16: 43.1
B17: amazon abonnement annuel | I17: 44.5
A18: Total | C18: =SUM(C10:C17) -> 33 | D18: =SUM(D10:D17) -> 146 | I18: 23.8
A19: Loisirs | B19: Restaurant | I19: 35
B20: Week-end/vacances | C20: =15+50+180+118+35 -> 398 | D20: =45+144 -> 189 | I20: 15.8
I21: 13.6
B22: Livres | I22: 33.3
A23: Total | C23: =SUM(C19:C22) -> 398 | D23: =SUM(D19:D22) -> 189 | I23: 10.3
A24: Vie quotidienne | B24: pharmacie | I24: 17
B25: Berlioz/rats | D25: 92 | I25: 10.4
B26: Sport | I26: 21
B27: Cadeaux | I27: 34.5
B28: Appartement | I28: 2.6
B29: Immo | I29: 16.3
A30: Total | C30: =sum(C24:C29) -> 0 | D30: =sum(D24:D29) -> 92 | I30: 17.7
A31: Total | I31: =SUM(I7:I30) -> 501.8
A32: Total Chris | D32: =C9+C18+C23+C30 -> 431
A33: Total Alex | D33: =D9+D18+D23+D30 -> 607
A34: Balance | D34: =(D33-D32)/2 -> 88
A36: Dettes:
A38: Chris → Alex | B38: Montant | E38: Alex → Chris | F38: Montant | H38: Balance finale (Chris->Alex) | I38: =B45-F45 -> -290
A39: Balance courante | B39: =D34 -> 88 | E39: Virement | F39: 600
A40: Balence précédente | B40: -27
A41: appart | B41: 115
B42: 40
A43: maroc | B43: 85
...

Sheet mars 2026
A1: Catégorie | B1: Sous catégorie | C1: Chris | D1: Alex
A2: Alimentation | B2: marché/pain
B3: miel
B4: Viande
B5: Intermarché
A7: Habitation | B7: Loyer | I7: 4.5
I8: 13.6
C9: =SUM(C2:C8) -> 0 | D9: =SUM(D2:D8) -> 0 | I9: 38.4
B10: Assurance | D10: 31 | I10: 10.3
B11: Impôt | I11: 33
B12: Eau | D12: 115 | I12: 12.5
B13: direct énergie | I13: 2.6
B14: Internet | C14: =33 -> 33 | I14: 31.7
B15: Taxe habitation | I15: 16.3
B16: Ramonage | I16: 43.1
B17: amazon abonnement annuel | I17: 44.5
A18: Total | C18: =SUM(C10:C17) -> 33 | D18: =SUM(D10:D17) -> 146 | I18: 23.8
A19: Loisirs | B19: Restaurant | I19: 35
B20: Week-end/vacances | I20: 15.8
I21: 13.6
B22: Livres | I22: 33.3
A23: Total | C23: =SUM(C19:C22) -> 0 | D23: =SUM(D19:D22) -> 0 | I23: 10.3
A24: Vie quotidienne | B24: pharmacie | I24: 17
B25: Berlioz/rats | I25: 10.4
B26: Sport | I26: 21
B27: Cadeaux | I27: 34.5
B28: Appartement | I28: 2.6
B29: Immo | I29: 16.3
A30: Total | C30: =sum(C24:C29) -> 0 | D30: =sum(D24:D29) -> 0 | I30: 17.7
A31: Total | I31: =SUM(I7:I30) -> 501.8
A32: Total Chris | D32: =C9+C18+C23+C30 -> 33
A33: Total Alex | D33: =D9+D18+D23+D30 -> 146
A34: Balance | D34: =(D33-D32)/2 -> 56.5
A36: Dettes:
A38: Chris → Alex | B38: Montant | E38: Alex → Chris | F38: Montant | H38: Balance finale (Chris->Alex) | I38: =B45-F45 -> -518.5
A39: Balance courante | B39: =D34 -> 56.5 | E39: Virement | F39: 400
A40: Balence précédente | B40: -290
A41: appart | B41: 115
A45: Total | B45: =sum(B39:B44) -> -118.5 | E45: Total | F45: =sum(F39:F44) -> 400

Sheet Alex appart
A2: Mois | B2: Catégorie | C2: Libellé | D2: Montant | F2: Total Alex | G2: =sum(D3:D148) -> 1299
A3: 42917 | B3: Intérieur | C3: Rideau | D3: 260
A4: 42979 | B4: Crédit | D4: =534-120 -> 414
A5: 43009 | B5: Radiateur | C5: Equipement | D5: 319
A6: 43009 | B6: Radiateur | C6: Fixation & Prise elcs | D6: 40
A7: 43009 | B7: Chauffe eau | C7: Mitigeur themostatique | D7: 120
A8: 43009 | B8: Peinture & Ponçage | D8: 86
A9: 43040 | C9: vernis porte | D9: 60

Sheet Ammortissement Appart
B1: Crédit | C1: Chris | D1: Alex | G1: Total Chris | H1: =SUM(C5:C69) -> 7776
A2: 45109 | B2: 1718 | G2: Total Alex | H2: =SUM(D6:D70) -> 25956.41
A3: 45112 | B3: 0 | G3: Mensualités restantes: | H3: =COUNTBLANK(D5:D304) -> 235
A4: 45143 | B4: 152 | G4: Total emprunt | H4: =sum(B2:B304) -> 154494.34
A5: 42983 | B5: 533.93 | C5: 120 | D5: =B5-C5 -> 413.93 | G5: Reste à rembourser: | H5: =H4-(H1+H2) -> 120761.93
A6: 43013 | B6: 533.93 | C6: 123 | D6: =B6-C6 -> 410.93
A7: 43044 | B7: 533.93 | C7: 123 | D7: =B7-C7 -> 410.93
A8: 43074 | B8: 533.93 | C8: 123 | D8: =B8-C8 -> 410.93
A9: 43105 | B9: 533.93 | C9: 123 | D9: =B9-C9 -> 410.93
A10: 43136 | B10: 533.93 | C10: 123 | D10: =B10-C10 -> 410.93
A11: 43164 | B11: 533.93 | C11: 123 | D11: =B11-C11 -> 410.93
A12: 43195 | B12: 533.93 | C12: 123 | D12: =B12-C12 -> 410.93
A13: 43225 | B13: 533.93 | C13: 123 | D13: =B13-C13 -> 410.93
A14: 43256 | B14: 533.93 | C14: 123 | D14: =B14-C14 -> 410.93
A15: 43286 | B15: 533.93 | C15: 123 | D15: =B15-C15 -> 410.93
A16: 43317 | B16: 533.93 | C16: 123 | D16: =B16-C16 -> 410.93
A17: 43348 | B17: 533.93 | C17: 123 | D17: =B17-C17 -> 410.93
... A69: 44931 | B69: 513 | C69: 115 | D69: =B69-C69 -> 398
A70: 44962 | B70: 513
A71: 44990 | B71: 513
A72: 45021 | B72: 513
A73: 45051 | B73: 512
A74: 45082 | B74: 512
A75: 45112 | B75: 512
A76: 45143 | B76: 512
A77: 45174 | B77: 512
A78: 45204 | B78: 512
A79: 45235 | B79: 512
A80: 45265 | B80: 512
A81: 45296 | B81: 512
... A304: 52083 | B304: 495
B306: =AVERAGE(B70:B304) -> 504.1617

Sheet Chris appart
A2: Mois | B2: Catégorie | C2: Libellé | D2: Montant | F2: Total Chris | G2: =sum(D3:D150) -> 87520
A3: 42887 | B3: Capital | C3: Apport LCL | D3: 73200
A4: 42887 | B4: Cuisine | C4: Pose/installation | D4: 1410
A5: 42887 | B5: Notaire | C5: Accompte | D5: 9200
A6: 42975 | B6: Cuisine | C6: Pose/installation | D6: =5000-1410 -> 3590
A7: 42979 | B7: Credit | D7: 120

Sheet Synthèse appart
A2: Coût total emprunt | B2: 160179
A3: Montant emprunté | B3: 116000
